2019-04-09 21:05:28,099 INFO: Microblog startup [in /Users/Mark/Documents/GitHub/Fantasy_Football/Website/app/__init__.py:49]
2019-04-09 21:06:01,418 INFO: Microblog startup [in /Users/Mark/Documents/GitHub/Fantasy_Football/Website/app/__init__.py:49]
2019-04-09 21:06:37,596 INFO: Microblog startup [in /Users/Mark/Documents/GitHub/Fantasy_Football/Website/app/__init__.py:49]
2019-04-09 21:06:42,639 INFO: Microblog startup [in /Users/Mark/Documents/GitHub/Fantasy_Football/Website/app/__init__.py:49]
2019-04-09 21:07:01,153 INFO: Microblog startup [in /Users/Mark/Documents/GitHub/Fantasy_Football/Website/app/__init__.py:49]
2019-04-09 21:07:08,739 ERROR: Exception on / [GET] [in /Users/Mark/anaconda3/lib/python3.6/site-packages/flask/app.py:1761]
Traceback (most recent call last):
  File "/Users/Mark/anaconda3/lib/python3.6/site-packages/sqlalchemy/ext/declarative/clsregistry.py", line 281, in __call__
    x = eval(self.arg, globals(), self._dict)
  File "<string>", line 1, in <module>
NameError: name 'Post' is not defined

During handling of the above exception, another exception occurred:

Traceback (most recent call last):
  File "/Users/Mark/anaconda3/lib/python3.6/site-packages/flask/app.py", line 2292, in wsgi_app
    response = self.full_dispatch_request()
  File "/Users/Mark/anaconda3/lib/python3.6/site-packages/flask/app.py", line 1815, in full_dispatch_request
    rv = self.handle_user_exception(e)
  File "/Users/Mark/anaconda3/lib/python3.6/site-packages/flask/app.py", line 1718, in handle_user_exception
    reraise(exc_type, exc_value, tb)
  File "/Users/Mark/anaconda3/lib/python3.6/site-packages/flask/_compat.py", line 35, in reraise
    raise value
  File "/Users/Mark/anaconda3/lib/python3.6/site-packages/flask/app.py", line 1811, in full_dispatch_request
    rv = self.preprocess_request()
  File "/Users/Mark/anaconda3/lib/python3.6/site-packages/flask/app.py", line 2087, in preprocess_request
    rv = func()
  File "/Users/Mark/Documents/GitHub/Fantasy_Football/Website/app/routes.py", line 84, in before_request
    if current_user.is_authenticated:
  File "/Users/Mark/.local/lib/python3.6/site-packages/werkzeug/local.py", line 348, in __getattr__
    return getattr(self._get_current_object(), name)
  File "/Users/Mark/.local/lib/python3.6/site-packages/werkzeug/local.py", line 307, in _get_current_object
    return self.__local()
  File "/Users/Mark/anaconda3/lib/python3.6/site-packages/flask_login/utils.py", line 26, in <lambda>
    current_user = LocalProxy(lambda: _get_user())
  File "/Users/Mark/anaconda3/lib/python3.6/site-packages/flask_login/utils.py", line 335, in _get_user
    current_app.login_manager._load_user()
  File "/Users/Mark/anaconda3/lib/python3.6/site-packages/flask_login/login_manager.py", line 359, in _load_user
    return self.reload_user()
  File "/Users/Mark/anaconda3/lib/python3.6/site-packages/flask_login/login_manager.py", line 321, in reload_user
    user = self.user_callback(user_id)
  File "/Users/Mark/Documents/GitHub/Fantasy_Football/Website/app/models.py", line 63, in load_user
    return User.query.get(int(id))
  File "/Users/Mark/anaconda3/lib/python3.6/site-packages/flask_sqlalchemy/__init__.py", line 512, in __get__
    mapper = orm.class_mapper(type)
  File "/Users/Mark/anaconda3/lib/python3.6/site-packages/sqlalchemy/orm/base.py", line 421, in class_mapper
    mapper = _inspect_mapped_class(class_, configure=configure)
  File "/Users/Mark/anaconda3/lib/python3.6/site-packages/sqlalchemy/orm/base.py", line 400, in _inspect_mapped_class
    mapper._configure_all()
  File "/Users/Mark/anaconda3/lib/python3.6/site-packages/sqlalchemy/orm/mapper.py", line 1222, in _configure_all
    configure_mappers()
  File "/Users/Mark/anaconda3/lib/python3.6/site-packages/sqlalchemy/orm/mapper.py", line 2872, in configure_mappers
    mapper._post_configure_properties()
  File "/Users/Mark/anaconda3/lib/python3.6/site-packages/sqlalchemy/orm/mapper.py", line 1765, in _post_configure_properties
    prop.init()
  File "/Users/Mark/anaconda3/lib/python3.6/site-packages/sqlalchemy/orm/interfaces.py", line 184, in init
    self.do_init()
  File "/Users/Mark/anaconda3/lib/python3.6/site-packages/sqlalchemy/orm/relationships.py", line 1653, in do_init
    self._process_dependent_arguments()
  File "/Users/Mark/anaconda3/lib/python3.6/site-packages/sqlalchemy/orm/relationships.py", line 1710, in _process_dependent_arguments
    self.target = self.mapper.mapped_table
  File "/Users/Mark/anaconda3/lib/python3.6/site-packages/sqlalchemy/util/langhelpers.py", line 764, in __get__
    obj.__dict__[self.__name__] = result = self.fget(obj)
  File "/Users/Mark/anaconda3/lib/python3.6/site-packages/sqlalchemy/orm/relationships.py", line 1626, in mapper
    argument = self.argument()
  File "/Users/Mark/anaconda3/lib/python3.6/site-packages/sqlalchemy/ext/declarative/clsregistry.py", line 293, in __call__
    (self.prop.parent, self.arg, n.args[0], self.cls)
sqlalchemy.exc.InvalidRequestError: When initializing mapper Mapper|User|user, expression 'Post' failed to locate a name ("name 'Post' is not defined"). If this is a class name, consider adding this relationship() to the <class 'app.models.User'> class after both dependent classes have been defined.
2019-04-09 21:09:45,697 INFO: Microblog startup [in /Users/Mark/Documents/GitHub/Fantasy_Football/Website/app/__init__.py:49]
2019-04-09 21:09:48,940 ERROR: Exception on / [GET] [in /Users/Mark/anaconda3/lib/python3.6/site-packages/flask/app.py:1761]
Traceback (most recent call last):
  File "/Users/Mark/anaconda3/lib/python3.6/site-packages/sqlalchemy/ext/declarative/clsregistry.py", line 281, in __call__
    x = eval(self.arg, globals(), self._dict)
  File "<string>", line 1, in <module>
NameError: name 'Post' is not defined

During handling of the above exception, another exception occurred:

Traceback (most recent call last):
  File "/Users/Mark/anaconda3/lib/python3.6/site-packages/flask/app.py", line 2292, in wsgi_app
    response = self.full_dispatch_request()
  File "/Users/Mark/anaconda3/lib/python3.6/site-packages/flask/app.py", line 1815, in full_dispatch_request
    rv = self.handle_user_exception(e)
  File "/Users/Mark/anaconda3/lib/python3.6/site-packages/flask/app.py", line 1718, in handle_user_exception
    reraise(exc_type, exc_value, tb)
  File "/Users/Mark/anaconda3/lib/python3.6/site-packages/flask/_compat.py", line 35, in reraise
    raise value
  File "/Users/Mark/anaconda3/lib/python3.6/site-packages/flask/app.py", line 1811, in full_dispatch_request
    rv = self.preprocess_request()
  File "/Users/Mark/anaconda3/lib/python3.6/site-packages/flask/app.py", line 2087, in preprocess_request
    rv = func()
  File "/Users/Mark/Documents/GitHub/Fantasy_Football/Website/app/routes.py", line 84, in before_request
    if current_user.is_authenticated:
  File "/Users/Mark/.local/lib/python3.6/site-packages/werkzeug/local.py", line 348, in __getattr__
    return getattr(self._get_current_object(), name)
  File "/Users/Mark/.local/lib/python3.6/site-packages/werkzeug/local.py", line 307, in _get_current_object
    return self.__local()
  File "/Users/Mark/anaconda3/lib/python3.6/site-packages/flask_login/utils.py", line 26, in <lambda>
    current_user = LocalProxy(lambda: _get_user())
  File "/Users/Mark/anaconda3/lib/python3.6/site-packages/flask_login/utils.py", line 335, in _get_user
    current_app.login_manager._load_user()
  File "/Users/Mark/anaconda3/lib/python3.6/site-packages/flask_login/login_manager.py", line 359, in _load_user
    return self.reload_user()
  File "/Users/Mark/anaconda3/lib/python3.6/site-packages/flask_login/login_manager.py", line 321, in reload_user
    user = self.user_callback(user_id)
  File "/Users/Mark/Documents/GitHub/Fantasy_Football/Website/app/models.py", line 63, in load_user
    return User.query.get(int(id))
  File "/Users/Mark/anaconda3/lib/python3.6/site-packages/flask_sqlalchemy/__init__.py", line 512, in __get__
    mapper = orm.class_mapper(type)
  File "/Users/Mark/anaconda3/lib/python3.6/site-packages/sqlalchemy/orm/base.py", line 421, in class_mapper
    mapper = _inspect_mapped_class(class_, configure=configure)
  File "/Users/Mark/anaconda3/lib/python3.6/site-packages/sqlalchemy/orm/base.py", line 400, in _inspect_mapped_class
    mapper._configure_all()
  File "/Users/Mark/anaconda3/lib/python3.6/site-packages/sqlalchemy/orm/mapper.py", line 1222, in _configure_all
    configure_mappers()
  File "/Users/Mark/anaconda3/lib/python3.6/site-packages/sqlalchemy/orm/mapper.py", line 2872, in configure_mappers
    mapper._post_configure_properties()
  File "/Users/Mark/anaconda3/lib/python3.6/site-packages/sqlalchemy/orm/mapper.py", line 1765, in _post_configure_properties
    prop.init()
  File "/Users/Mark/anaconda3/lib/python3.6/site-packages/sqlalchemy/orm/interfaces.py", line 184, in init
    self.do_init()
  File "/Users/Mark/anaconda3/lib/python3.6/site-packages/sqlalchemy/orm/relationships.py", line 1653, in do_init
    self._process_dependent_arguments()
  File "/Users/Mark/anaconda3/lib/python3.6/site-packages/sqlalchemy/orm/relationships.py", line 1710, in _process_dependent_arguments
    self.target = self.mapper.mapped_table
  File "/Users/Mark/anaconda3/lib/python3.6/site-packages/sqlalchemy/util/langhelpers.py", line 764, in __get__
    obj.__dict__[self.__name__] = result = self.fget(obj)
  File "/Users/Mark/anaconda3/lib/python3.6/site-packages/sqlalchemy/orm/relationships.py", line 1626, in mapper
    argument = self.argument()
  File "/Users/Mark/anaconda3/lib/python3.6/site-packages/sqlalchemy/ext/declarative/clsregistry.py", line 293, in __call__
    (self.prop.parent, self.arg, n.args[0], self.cls)
sqlalchemy.exc.InvalidRequestError: When initializing mapper Mapper|User|user, expression 'Post' failed to locate a name ("name 'Post' is not defined"). If this is a class name, consider adding this relationship() to the <class 'app.models.User'> class after both dependent classes have been defined.
2019-04-09 21:10:14,909 INFO: Microblog startup [in /Users/Mark/Documents/GitHub/Fantasy_Football/Website/app/__init__.py:49]
