2019-04-03 19:58:03,767 ERROR: Exception on /login [GET] [in /Users/Mark/anaconda3/lib/python3.6/site-packages/flask/app.py:1761]
Traceback (most recent call last):
  File "/Users/Mark/anaconda3/lib/python3.6/site-packages/flask/app.py", line 2292, in wsgi_app
    response = self.full_dispatch_request()
  File "/Users/Mark/anaconda3/lib/python3.6/site-packages/flask/app.py", line 1815, in full_dispatch_request
    rv = self.handle_user_exception(e)
  File "/Users/Mark/anaconda3/lib/python3.6/site-packages/flask/app.py", line 1718, in handle_user_exception
    reraise(exc_type, exc_value, tb)
  File "/Users/Mark/anaconda3/lib/python3.6/site-packages/flask/_compat.py", line 35, in reraise
    raise value
  File "/Users/Mark/anaconda3/lib/python3.6/site-packages/flask/app.py", line 1813, in full_dispatch_request
    rv = self.dispatch_request()
  File "/Users/Mark/anaconda3/lib/python3.6/site-packages/flask/app.py", line 1799, in dispatch_request
    return self.view_functions[rule.endpoint](**req.view_args)
  File "/Users/Mark/Documents/GitHub/Flasky/app/routes.py", line 70, in login
    return render_template('login.html', title='Sign In', form=form)
  File "/Users/Mark/anaconda3/lib/python3.6/site-packages/flask/templating.py", line 135, in render_template
    context, ctx.app)
  File "/Users/Mark/anaconda3/lib/python3.6/site-packages/flask/templating.py", line 117, in _render
    rv = template.render(context)
  File "/Users/Mark/anaconda3/lib/python3.6/site-packages/jinja2/asyncsupport.py", line 76, in render
    return original_render(self, *args, **kwargs)
  File "/Users/Mark/anaconda3/lib/python3.6/site-packages/jinja2/environment.py", line 1008, in render
    return self.environment.handle_exception(exc_info, True)
  File "/Users/Mark/anaconda3/lib/python3.6/site-packages/jinja2/environment.py", line 780, in handle_exception
    reraise(exc_type, exc_value, tb)
  File "/Users/Mark/anaconda3/lib/python3.6/site-packages/jinja2/_compat.py", line 37, in reraise
    raise value.with_traceback(tb)
  File "/Users/Mark/Documents/GitHub/Flasky/app/templates/login.html", line 1, in top-level template code
    {% extends "base.html" %}
  File "/Users/Mark/Documents/GitHub/Flasky/app/templates/base.html", line 31, in top-level template code
    {% block content %}{% endblock %}
  File "/Users/Mark/Documents/GitHub/Flasky/app/templates/login.html", line 25, in block "content"
    <p>Forgot Your Password? <a href="{{ url_for('reset_password_request') }}">Click to Reset It</a></p>
  File "/Users/Mark/anaconda3/lib/python3.6/site-packages/flask/helpers.py", line 356, in url_for
    return appctx.app.handle_url_build_error(error, endpoint, values)
  File "/Users/Mark/anaconda3/lib/python3.6/site-packages/flask/app.py", line 2061, in handle_url_build_error
    reraise(exc_type, exc_value, tb)
  File "/Users/Mark/anaconda3/lib/python3.6/site-packages/flask/_compat.py", line 35, in reraise
    raise value
  File "/Users/Mark/anaconda3/lib/python3.6/site-packages/flask/helpers.py", line 345, in url_for
    force_external=external)
  File "/Users/Mark/.local/lib/python3.6/site-packages/werkzeug/routing.py", line 2182, in build
    raise BuildError(endpoint, values, method, self)
werkzeug.routing.BuildError: Could not build url for endpoint 'reset_password_request'. Did you mean 'edit_profile' instead?
2019-04-03 21:04:14,688 INFO: Microblog startup [in /Users/Mark/Documents/GitHub/Flasky/app/__init__.py:45]
2019-04-03 21:07:13,133 INFO: Microblog startup [in /Users/Mark/Documents/GitHub/Flasky/app/__init__.py:45]
2019-04-03 21:19:07,733 INFO: Microblog startup [in /Users/Mark/Documents/GitHub/Flasky/app/__init__.py:45]
2019-04-03 21:19:30,997 INFO: Microblog startup [in /Users/Mark/Documents/GitHub/Flasky/app/__init__.py:45]
2019-04-06 08:49:36,531 INFO: Microblog startup [in /Users/Mark/Documents/GitHub/Flasky/app/__init__.py:45]
2019-04-06 08:52:20,159 INFO: Microblog startup [in /Users/Mark/Documents/GitHub/Flasky/app/__init__.py:45]
2019-04-06 09:04:56,708 INFO: Microblog startup [in /Users/Mark/Documents/GitHub/Flasky/app/__init__.py:45]
2019-04-06 09:10:47,417 INFO: Microblog startup [in /Users/Mark/Documents/GitHub/Flasky/app/__init__.py:45]
2019-04-06 09:24:45,992 INFO: Microblog startup [in /Users/Mark/Documents/GitHub/Flasky/app/__init__.py:45]
2019-04-06 09:45:42,983 INFO: Microblog startup [in /Users/Mark/Documents/GitHub/Flasky/app/__init__.py:47]
2019-04-06 09:55:35,015 INFO: Microblog startup [in /Users/Mark/Documents/GitHub/Flasky/app/__init__.py:47]
2019-04-06 09:58:09,378 INFO: Microblog startup [in /Users/Mark/Documents/GitHub/Flasky/app/__init__.py:47]
2019-04-06 11:29:31,618 ERROR: Exception on /edit_profile [GET] [in /Users/Mark/anaconda3/lib/python3.6/site-packages/flask/app.py:1761]
Traceback (most recent call last):
  File "/Users/Mark/anaconda3/lib/python3.6/site-packages/flask/app.py", line 2292, in wsgi_app
    response = self.full_dispatch_request()
  File "/Users/Mark/anaconda3/lib/python3.6/site-packages/flask/app.py", line 1815, in full_dispatch_request
    rv = self.handle_user_exception(e)
  File "/Users/Mark/anaconda3/lib/python3.6/site-packages/flask/app.py", line 1718, in handle_user_exception
    reraise(exc_type, exc_value, tb)
  File "/Users/Mark/anaconda3/lib/python3.6/site-packages/flask/_compat.py", line 35, in reraise
    raise value
  File "/Users/Mark/anaconda3/lib/python3.6/site-packages/flask/app.py", line 1813, in full_dispatch_request
    rv = self.dispatch_request()
  File "/Users/Mark/anaconda3/lib/python3.6/site-packages/flask/app.py", line 1799, in dispatch_request
    return self.view_functions[rule.endpoint](**req.view_args)
  File "/Users/Mark/anaconda3/lib/python3.6/site-packages/flask_login/utils.py", line 261, in decorated_view
    return func(*args, **kwargs)
  File "/Users/Mark/Documents/GitHub/Flasky/app/routes.py", line 131, in edit_profile
    return render_template('edit_profile.html', title='Edit Profile', form=form)
  File "/Users/Mark/anaconda3/lib/python3.6/site-packages/flask/templating.py", line 135, in render_template
    context, ctx.app)
  File "/Users/Mark/anaconda3/lib/python3.6/site-packages/flask/templating.py", line 117, in _render
    rv = template.render(context)
  File "/Users/Mark/anaconda3/lib/python3.6/site-packages/jinja2/asyncsupport.py", line 76, in render
    return original_render(self, *args, **kwargs)
  File "/Users/Mark/anaconda3/lib/python3.6/site-packages/jinja2/environment.py", line 1008, in render
    return self.environment.handle_exception(exc_info, True)
  File "/Users/Mark/anaconda3/lib/python3.6/site-packages/jinja2/environment.py", line 780, in handle_exception
    reraise(exc_type, exc_value, tb)
  File "/Users/Mark/anaconda3/lib/python3.6/site-packages/jinja2/_compat.py", line 37, in reraise
    raise value.with_traceback(tb)
  File "/Users/Mark/Documents/GitHub/Flasky/app/templates/edit_profile.html", line 1, in top-level template code
    {% extends "base.html" %}
jinja2.exceptions.TemplateRuntimeError: extended multiple times
2019-04-06 11:30:08,527 ERROR: Exception on /edit_profile [GET] [in /Users/Mark/anaconda3/lib/python3.6/site-packages/flask/app.py:1761]
Traceback (most recent call last):
  File "/Users/Mark/anaconda3/lib/python3.6/site-packages/flask/app.py", line 2292, in wsgi_app
    response = self.full_dispatch_request()
  File "/Users/Mark/anaconda3/lib/python3.6/site-packages/flask/app.py", line 1815, in full_dispatch_request
    rv = self.handle_user_exception(e)
  File "/Users/Mark/anaconda3/lib/python3.6/site-packages/flask/app.py", line 1718, in handle_user_exception
    reraise(exc_type, exc_value, tb)
  File "/Users/Mark/anaconda3/lib/python3.6/site-packages/flask/_compat.py", line 35, in reraise
    raise value
  File "/Users/Mark/anaconda3/lib/python3.6/site-packages/flask/app.py", line 1813, in full_dispatch_request
    rv = self.dispatch_request()
  File "/Users/Mark/anaconda3/lib/python3.6/site-packages/flask/app.py", line 1799, in dispatch_request
    return self.view_functions[rule.endpoint](**req.view_args)
  File "/Users/Mark/anaconda3/lib/python3.6/site-packages/flask_login/utils.py", line 261, in decorated_view
    return func(*args, **kwargs)
  File "/Users/Mark/Documents/GitHub/Flasky/app/routes.py", line 131, in edit_profile
    return render_template('edit_profile.html', title='Edit Profile', form=form)
  File "/Users/Mark/anaconda3/lib/python3.6/site-packages/flask/templating.py", line 135, in render_template
    context, ctx.app)
  File "/Users/Mark/anaconda3/lib/python3.6/site-packages/flask/templating.py", line 117, in _render
    rv = template.render(context)
  File "/Users/Mark/anaconda3/lib/python3.6/site-packages/jinja2/asyncsupport.py", line 76, in render
    return original_render(self, *args, **kwargs)
  File "/Users/Mark/anaconda3/lib/python3.6/site-packages/jinja2/environment.py", line 1008, in render
    return self.environment.handle_exception(exc_info, True)
  File "/Users/Mark/anaconda3/lib/python3.6/site-packages/jinja2/environment.py", line 780, in handle_exception
    reraise(exc_type, exc_value, tb)
  File "/Users/Mark/anaconda3/lib/python3.6/site-packages/jinja2/_compat.py", line 37, in reraise
    raise value.with_traceback(tb)
  File "/Users/Mark/Documents/GitHub/Flasky/app/templates/edit_profile.html", line 1, in top-level template code
    {% extends "base.html" %}
jinja2.exceptions.TemplateRuntimeError: extended multiple times
2019-04-06 11:32:45,107 INFO: Microblog startup [in /Users/Mark/Documents/GitHub/Flasky/app/__init__.py:47]
2019-04-09 19:36:38,040 INFO: Microblog startup [in /Users/Mark/Documents/GitHub/Flasky/app/__init__.py:49]
2019-04-09 19:42:38,144 INFO: Microblog startup [in /Users/Mark/Documents/GitHub/Flasky/app/__init__.py:49]
2019-04-09 20:03:54,052 INFO: Microblog startup [in /Users/Mark/Documents/GitHub/Flasky/app/__init__.py:49]
2019-04-09 20:58:34,299 INFO: Microblog startup [in /Users/Mark/Documents/GitHub/Fantasy_Football/Website/app/__init__.py:49]
2019-04-09 21:03:48,358 INFO: Microblog startup [in /Users/Mark/Documents/GitHub/Fantasy_Football/Website/app/__init__.py:49]
